<mujoco model="hinge">
	<include file="shared_config.xml"/>
	<worldbody >
		<include file="sawyer_xyz_base_no_table.xml"/>
		<body name="box" pos="0 0.6 0.07" axisangle="0 0 1 1.3024572521124422">
			<inertial pos="0 0 0" mass="1" diaginertia="1 1 1"/>
			<geom pos="0 0 0" name="base_obj" type="box" size="0.07 0.07 0.07" rgba="0.3 1 0.3 1" contype="1" conaffinity="1"/>
		</body>
		<body name="box2" pos="0 0.6 0.07" axisangle="0 0 1 1.3024572521124422">
			<inertial pos="0 0 0" mass="1" diaginertia="1e-6 1e-6 1e-6"/>
			<geom pos="0 0.11000000000000001 0" name="target_obj" type="box" size="0.09 0.02 0.09" rgba="0.3 .3 1 1" contype="1" conaffinity="1"/>
			<joint pos="0.07 0 0" name="hinge" range="-3 3" axis="0 0 1" damping=".001" armature="0"/>
		</body>
	</worldbody>
	<actuator >
		<position ctrllimited="true" ctrlrange="-1 1" joint="r_close" kp="400" user="1"/>
		<position ctrllimited="true" ctrlrange="-1 1" joint="l_close" kp="400" user="1"/>
	</actuator>
</mujoco>
